<robot name="right_robot_inhand">

  <!-- material definition-->
  
  <material name = "robot_grey">
    <color rgba="0.7 0.7 0.7 1" />
  </material>

  <material name="gripper_black">
    <color rgba="0.1 0.1 0.1 1"/>
  </material>      
  
  <material name="gripper_white">
    <color rgba="0.9 0.9 0.9 1"/>
  </material>

  <material name="gripper_grey">
    <color rgba="0.792156862745098 0.819607843137255 0.933333333333333 1"/>
  </material>

  <!-- joints of right arm -->

  <joint name="joint1" type="revolute">
    <parent link="base_link"/>
    <child link="link1"/>
    <origin rpy="0 3.141592653589793 0" xyz="0 0 0.155"/>
    <axis xyz="0 0 1"/>
    <limit effort="123" lower="-2.7925" upper="2.7925" velocity="2.0944"/>
  </joint>

  <joint name="joint2" type="revolute">
    <parent link="link1"/>
    <child link="link2"/>
    <origin rpy="0 0 3.141592653589793" xyz="0.0 0.03 -0.210"/>
    <axis xyz="0 1 0"/>
    <limit effort="123" lower="-2.2689" upper="2.2689" velocity="2.0944"/>
  </joint>

  <joint name="joint3" type="revolute">
    <parent link="link2"/>
    <child link="link3"/>
    <origin rpy="0 0 3.141592653589793" xyz="0.0 -0.035 -0.205"/>
    <axis xyz="0 0 1"/>
    <limit effort="64" lower="-2.9671" upper="2.9671" velocity="2.4435"/>
  </joint>

  <joint name="joint4" type="revolute">
    <parent link="link3"/>
    <child link="link4"/>
    <origin rpy="0 0 0" xyz="-0.02 -0.03 -0.19"/>
    <axis xyz="0 1 0"/>
    <limit effort="64" lower="-1.8675" upper="2.6878" velocity="2.4435"/>
  </joint>

  <joint name="joint5" type="revolute">
    <parent link="link4"/>
    <child link="link5"/>
    <origin rpy="0 0 0" xyz="0.02 -0.025 -0.195"/>
    <axis xyz="0 0 1"/>
    <limit effort="39" lower="-2.9671" upper="2.9671" velocity="4.8869"/>
  </joint>

  <joint name="joint6" type="revolute">
    <parent link="link5"/>
    <child link="link6"/>
    <origin rpy="0 0 3.141592653589793" xyz="0.0 0.03 -0.19"/>
    <axis xyz="0 1 0"/>
    <limit effort="39" lower="-1.3963" upper="4.5379" velocity="4.8869"/>
  </joint>

  <joint name="joint7" type="revolute">
    <parent link="link6"/>
    <child link="link7"/>
    <origin rpy="0 -1.5707963267948966 0" xyz="0.055 -0.070 -0.11"/>
    <axis xyz="0 0 1"/>
    <limit effort="39" lower="-2.9671" upper="2.9671" velocity="4.8869"/>
  </joint>

  <joint name="link7_to_flange" type="fixed">
    <parent link="link7"/>
    <child link="flange"/>
    <origin rpy="3.141592653589793 0 0" xyz="0.0 0.0 -0.081"/>
  </joint>

  <!-- links of right arm -->

  <link name="base_link">
    <inertial>
      <mass value="3.653"/>
      <origin rpy="0 0 0" xyz="0.0002 0.0006 0.0874"/>
      <inertia ixx="0.0194" ixy="0.0000" ixz="0.0000" iyy="0.0196" iyz="-0.0001" izz="0.0088"/>
    </inertial>
    <visual>
      <origin rpy="0 0 3.141592653589793" xyz="0 0 0"/>
      <geometry>
        <mesh filename="meshes/flexiv_arm/visual/link0.obj"/>
      </geometry>
      <material name="robot_grey" />
    </visual>
    <collision>
      <origin rpy="0 0 3.141592653589793" xyz="0 0 0"/>
      <geometry>
        <mesh filename="meshes/flexiv_arm/collision/link0.stl"/>
      </geometry>
    </collision>
  </link>

  <link name="link1">
    <inertial>
      <mass value="3.673"/>
      <origin rpy="0 0 0" xyz="0.0000 0.0060 -0.1489"/>
      <inertia ixx="0.0276" ixy="0.0000" ixz="0.0000" iyy="0.0272" iyz="-0.0017" izz="0.0077"/>
    </inertial>
    <visual>
      <origin rpy="0 3.141592653589793 0" xyz="0 0 0"/>
      <geometry>
        <mesh filename="meshes/flexiv_arm/visual/link1.obj"/>
      </geometry>
      <material name="robot_grey" />
    </visual>
    <collision>
      <origin rpy="0 3.141592653589793 0" xyz="0 0 0"/>
      <geometry>
        <mesh filename="meshes/flexiv_arm/collision/link1.stl"/>
      </geometry>
    </collision>
  </link>

  <link name="link2">
    <inertial>
      <mass value="2.734"/>
      <origin rpy="0 0 0" xyz="0.0000 -0.0362 -0.0979"/>
      <inertia ixx="0.0234" ixy="0.0000" ixz="0.0000" iyy="0.0243" iyz="-0.0003" izz="0.0036"/>
    </inertial>
    <visual>
      <origin rpy="3.141592653589793 0 0" xyz="0 0 0"/>
      <geometry>
        <mesh filename="meshes/flexiv_arm/visual/link2.obj"/>
      </geometry>
      <material name="robot_grey" />
    </visual>
    <collision>
      <origin rpy="3.141592653589793 0 0" xyz="0 0 0"/>
      <geometry>
        <mesh filename="meshes/flexiv_arm/collision/link2.stl"/>
      </geometry>
    </collision>
  </link>

  <link name="link3">
    <inertial>
      <mass value="2.397"/>
      <origin rpy="0 0 0" xyz="-0.0117 -0.0028 -0.1334"/>
      <inertia ixx="0.0141" ixy="0.0001" ixz="0.0014" iyy="0.0137" iyz="0.0007" izz="0.0038"/>
    </inertial>
    <visual>
      <origin rpy="0 3.141592653589793 0" xyz="0 0 0"/>
      <geometry>
        <mesh filename="meshes/flexiv_arm/visual/link3r.obj"/>
      </geometry>
      <material name="robot_grey" />
    </visual>
    <collision>
      <origin rpy="0 3.141592653589793 0" xyz="0 0 0"/>
      <geometry>
        <mesh filename="meshes/flexiv_arm/collision/link3r.obj"/>
      </geometry>
    </collision>
  </link>

  <link name="link4">
    <inertial>
      <mass value="2.397"/>
      <origin rpy="0 0 0" xyz="0.0126 -0.0312 -0.1013"/>
      <inertia ixx="0.0184" ixy="0.0001" ixz="-0.0016" iyy="0.0188" iyz="-0.0012" izz="0.0030"/>
    </inertial>
    <visual>
      <origin rpy="3.141592653589793 0 0" xyz="0 0 0"/>
      <geometry>
        <mesh filename="meshes/flexiv_arm/visual/link4r.obj"/>
      </geometry>
      <material name="robot_grey" />
    </visual>
    <collision>
      <origin rpy="3.141592653589793 0 0" xyz="0 0 0"/>
      <geometry>
        <mesh filename="meshes/flexiv_arm/collision/link4r.obj"/>
      </geometry>
    </collision>
  </link>

  <link name="link5">
    <inertial>
      <mass value="2.363"/>
      <origin rpy="0 0 0" xyz="0.0000 0.0032 -0.1328"/>
      <inertia ixx="0.0140" ixy="0.0000" ixz="0.0000" iyy="0.0134" iyz="-0.0007" izz="0.0036"/>
    </inertial>
    <visual>
      <origin rpy="0 3.141592653589793 0" xyz="0 0 0"/>
      <geometry>
        <mesh filename="meshes/flexiv_arm/visual/link5.obj"/>
      </geometry>
      <material name="robot_grey" />
    </visual>
    <collision>
      <origin rpy="0 3.141592653589793 0" xyz="0 0 0"/>
      <geometry>
        <mesh filename="meshes/flexiv_arm/collision/link5.stl"/>
      </geometry>
    </collision>
  </link>

  <link name="link6">
    <inertial>
      <mass value="2.135"/>
      <origin rpy="0 0 0" xyz="0.0093 -0.0567 -0.0694"/>
      <inertia ixx="0.0083" ixy="-0.0003" ixz="-0.0008" iyy="0.0086" iyz="0.0018" izz="0.0036"/>
    </inertial>
    <visual>
      <origin rpy="0 3.141592653589793 0" xyz="0 0 0"/>
      <geometry>
        <mesh filename="meshes/flexiv_arm/visual/link6r.obj"/>
      </geometry>
      <material name="robot_grey" />
    </visual>
    <collision>
      <origin rpy="0 3.141592653589793 0" xyz="0 0 0"/>
      <geometry>
        <mesh filename="meshes/flexiv_arm/collision/link6r.obj"/>
      </geometry>
    </collision>
  </link>

  <link name="link7">
    <inertial>
      <mass value="0.793"/>
      <origin rpy="0 0 0" xyz="0.0000 0.0003 -0.0250"/>
      <inertia ixx="0.0009" ixy="0.0000" ixz="0.0000" iyy="0.0010" iyz="0.0000" izz="0.0009"/>
    </inertial>
    <visual>
      <origin rpy="3.141592653589793 0 0" xyz="0 0 0"/>
      <geometry>
        <mesh filename="meshes/flexiv_arm/visual/link7_inhand_r.stl"/>
      </geometry>
      <material name="robot_grey" />
    </visual>
    <collision>
      <origin rpy="3.141592653589793 0 0" xyz="0 0 0"/>
      <geometry>
        <mesh filename="meshes/flexiv_arm/collision/link7_inhand_r.stl"/>
      </geometry>
    </collision>
  </link>

  <link name="flange">
    <inertial>
      <mass value="0.0" />
      <origin rpy="0 0 0" xyz="0.0 0.0 0.0" />
      <inertia ixx="0.0" ixy="0.0" ixz="0.0" iyy="0.0" iyz="0.0" izz="0.0" />
    </inertial>
  </link>

  <!-- right arm to gripper -->

  <joint name="flange2gripper" type="fixed">
    <parent link="flange" />
    <child link="robotiq_2f85_base_link" />
    <origin rpy="0.0 0.0 -1.5707963267948966" xyz="0.0 0.0 0.0" />
  </joint>

  <!-- right gripper -->
  
  <link name="robotiq_2f85_base_link">
    <inertial>
      <origin xyz="0.00021987 -2.3546E-10 0.030163" rpy="0 0 0" />
      <mass value="0.30915" />
      <inertia ixx="0.00028972" ixy="-5.7879E-10" ixz="-1.8543E-06" iyy="0.00030737" iyz="1.682E-12" izz="0.00019914" />
    </inertial>
    <visual>
      <origin xyz="0 0 0" rpy="0 0 0" />
      <geometry>
        <mesh filename="meshes/gripper/visual/robotiq_2f85_base_link.stl" />
      </geometry>
      <material name="gripper_black" />
    </visual>
    <collision>
      <origin xyz="0 0 0" rpy="0 0 0" />
      <geometry>
        <mesh filename="meshes/gripper/collision/robotiq_2f85_base_link.stl" />
      </geometry>
    </collision>
  </link>

  <link name="left_outer_knuckle">
    <inertial>
      <origin xyz="0.0178331863169983 3.68915177224286E-11 0.0021442477325704" rpy="0 0 0" />
      <mass value="0.00684838849434396" />
      <inertia ixx="2.66832029033166E-07" ixy="1.66142314639824E-15" ixz="1.45945633322873E-07" iyy="1.3889233257419E-06" iyz="2.82951161241588E-15" izz="1.26603336914415E-06" />
    </inertial>
    <visual>
      <origin xyz="0 0 0" rpy="0 0 0" />
      <geometry>
        <mesh filename="meshes/gripper/visual/outer_knuckle.stl" />
      </geometry>
      <material name="gripper_black" />
    </visual>
    <collision>
      <origin xyz="0 0 0" rpy="0 0 0" />
      <geometry>
        <mesh filename="meshes/gripper/collision/outer_knuckle.stl" />
      </geometry>
    </collision>
  </link>

  <joint name="finger_joint" type="revolute">
    <origin xyz="0.0306011444260539 0 0.0627920162695395" rpy="0 0 0" />
    <parent link="robotiq_2f85_base_link" />
    <child link="left_outer_knuckle" />
    <axis xyz="0 -1 0" />
    <limit lower="0" upper="0.725" velocity="2.0" effort="1000" />
  </joint>

  <link name="left_outer_finger">
    <inertial>
      <origin xyz="0.00131451599174296 2.88942057994543E-15 0.0215404163180413" rpy="0 0 0" />
      <mass value="0.0273093985570947" />
      <inertia ixx="8.51629628283022E-06" ixy="2.58174336207405E-19" ixz="3.83829504344079E-07" iyy="6.9133328065108E-06" iyz="-7.58589926143789E-19" izz="2.25006832221981E-06" />
    </inertial>
    <visual>
      <origin xyz="0 0 0" rpy="0 0 0" />
      <geometry>
        <mesh filename="meshes/gripper/visual/outer_finger.stl" />
      </geometry>
      <material name="gripper_black" />
    </visual>
    <collision>
      <origin xyz="0 0 0" rpy="0 0 0" />
      <geometry>
        <mesh filename="meshes/gripper/collision/outer_finger.stl" />
      </geometry>
    </collision>
  </link>

  <joint name="left_outer_finger_joint" type="fixed">
    <origin xyz="0.0316910442266543 0 -0.00193396375724605" rpy="0 0 0" />
    <parent link="left_outer_knuckle" />
    <child link="left_outer_finger" />
    <axis xyz="0 -1 0" />
  </joint>

  <link name="left_inner_knuckle">
    <inertial>
      <origin xyz="0.017097546626628 -3.93808524389535E-10 0.0224918438201868" rpy="0 0 0" />
      <mass value="0.0110930853895903" />
      <inertia ixx="4.23392770691541E-06" ixy="5.748978936968E-15" ixz="1.78855677119788E-06" iyy="3.96548790524392E-06" iyz="1.05464666369669E-14" izz="3.24068002883007E-06" />
    </inertial>
    <visual>
      <origin xyz="0 0 0" rpy="0 0 0" />
      <geometry>
        <mesh filename="meshes/gripper/visual/inner_knuckle.stl" />
      </geometry>
      <material name="gripper_black" />
    </visual>
    <collision>
      <origin xyz="0 0 0" rpy="0 0 0" />
      <geometry>
        <mesh filename="meshes/gripper/collision/inner_knuckle.stl" />
      </geometry>
    </collision>
  </link>

  <joint name="left_inner_knuckle_joint" type="revolute">
    <origin xyz="0.0127000000001501 0 0.0693074999999639" rpy="0 0 0" />
    <parent link="robotiq_2f85_base_link" />
    <child link="left_inner_knuckle" />
    <axis xyz="0 -1 0" />
    <limit lower="0" upper="0.8757" velocity="2.0" effort="1000" />
    <mimic joint="finger_joint" multiplier="1" offset="0" />
  </joint>

  <link name="left_inner_finger">
    <inertial>
      <origin xyz="0.0060275613594574 -6.29183141465421E-15 0.00669925693133241" rpy="0 0 0" />
      <mass value="0.00724255346165745" />
      <inertia ixx="1.47824274053603E-06" ixy="-3.94884463570303E-19" ixz="-3.45268847648622E-07" iyy="1.70064480838395E-06" iyz="3.5059838910097E-19" izz="4.77151336838364E-07" />
    </inertial>
    <visual>
      <origin xyz="0 0 0" rpy="0 0 0" />
      <geometry>
        <mesh filename="meshes/gripper/visual/inner_finger.stl" />
      </geometry>
      <material name="gripper_black" />
    </visual>
    <collision>
      <origin xyz="0 0 0" rpy="0 0 0" />
      <geometry>
        <mesh filename="meshes/gripper/collision/inner_finger.stl" />
      </geometry>
    </collision>
  </link>

  <joint name="left_inner_finger_joint" type="revolute">
    <origin xyz="0.034585310861294 0 0.0454970193817975" rpy="0 0 0" />
    <parent link="left_inner_knuckle" />
    <child link="left_inner_finger" />
    <axis xyz="0 -1 0" />
    <limit lower="0" upper="0.8757" velocity="2.0" effort="1000" />
    <mimic joint="finger_joint" multiplier="-1" offset="0" />
  </joint>

  <link name="right_inner_knuckle">
    <inertial>
      <origin xyz="0.0168606186773776 3.93808471820465E-10 0.0226699950793434" rpy="0 0 0" />
      <mass value="0.0110930853895903" />
      <inertia ixx="4.27134775939882E-06" ixy="-8.53568456728898E-15" ixz="1.77774229944246E-06" iyy="3.96548790524392E-06" iyz="-8.45108024914164E-15" izz="3.20325997634666E-06" />
    </inertial>
    <visual>
      <origin xyz="0 0 0" rpy="0 0 0" />
      <geometry>
        <mesh filename="meshes/gripper/visual/inner_knuckle.stl" />
      </geometry>
      <material name="gripper_black" />
    </visual>
    <collision>
      <origin xyz="0 0 0" rpy="0 0 0" />
      <geometry>
        <mesh filename="meshes/gripper/collision/inner_knuckle.stl" />
      </geometry>
    </collision>
  </link>

  <joint name="right_inner_knuckle_joint" type="revolute">
    <origin xyz="-0.0126999999998499 0 0.0693075000000361" rpy="0 0 3.14159265358979" />
    <parent link="robotiq_2f85_base_link" />
    <child link="right_inner_knuckle" />
    <axis xyz="0 1 0" />
    <limit lower="0" upper="0.8757" velocity="2.0" effort="1000" />
    <mimic joint="finger_joint" multiplier="-1" offset="0" />
  </joint>

  <link name="right_inner_finger">
    <inertial>
      <origin xyz="0.00602756228812038 -6.47284509480176E-15 0.00669925609578108" rpy="0 0 0" />
      <mass value="0.00724255346165744" />
      <inertia ixx="1.47824283625957E-06" ixy="-3.95952064019123E-19" ixz="-3.45268708875543E-07" iyy="1.70064480838394E-06" iyz="3.55286507960029E-19" izz="4.77151241114822E-07" />
    </inertial>
    <visual>
      <origin xyz="0 0 0" rpy="0 0 0" />
      <geometry>
        <mesh filename="meshes/gripper/visual/inner_finger.stl" />
      </geometry>
      <material name="gripper_black" />
    </visual>
    <collision>
      <origin xyz="0 0 0" rpy="0 0 0" />
      <geometry>
        <mesh filename="meshes/gripper/collision/inner_finger.stl" />
      </geometry>
    </collision>
  </link>

  <joint name="right_inner_finger_joint" type="revolute">
    <origin xyz="0.0341060475457406 0 0.0458573878541688" rpy="0 0 0" />
    <parent link="right_inner_knuckle" />
    <child link="right_inner_finger" />
    <axis xyz="0 1 0" />
    <limit lower="0" upper="0.8757" velocity="2.0" effort="1000" />
    <mimic joint="finger_joint" multiplier="1" offset="0" />
  </joint>

  <link name="right_outer_knuckle">
    <inertial>
      <origin xyz="0.0178097074051638 3.60493211424024E-11 0.00233123458346721" rpy="0 0 0" />
      <mass value="0.00684838849401352" />
      <inertia ixx="2.70004361573169E-07" ixy="1.59579467624491E-15" ixz="1.56396493788199E-07" iyy="1.38892332558312E-06" iyz="2.82357800318817E-15" izz="1.26286103637978E-06" />
    </inertial>
    <visual>
      <origin xyz="0 0 0" rpy="0 0 0" />
      <geometry>
        <mesh filename="meshes/gripper/visual/outer_knuckle.stl" />
      </geometry>
      <material name="gripper_black" />
    </visual>
    <collision>
      <origin xyz="0 0 0" rpy="0 0 0" />
      <geometry>
        <mesh filename="meshes/gripper/collision/outer_knuckle.stl" />
      </geometry>
    </collision>
  </link>

  <joint name="right_outer_knuckle_joint" type="revolute">
    <origin xyz="-0.0306011444258893 0 0.0627920162695395" rpy="0 0 3.14159265358979" />
    <parent link="robotiq_2f85_base_link" />
    <child link="right_outer_knuckle" />
    <axis xyz="0 1 0" />
    <limit lower="0" upper="0.8757" velocity="2.0" effort="1000" />
    <mimic joint="finger_joint" multiplier="-1" offset="0" />
  </joint>

  <link name="right_outer_finger">
    <inertial>
      <origin xyz="0.00108844269639009 -2.611488350845E-15 0.0215530225245502" rpy="0 0 0" />
      <mass value="0.0273093985570947" />
      <inertia ixx="8.52366028592721E-06" ixy="3.41683380899422E-19" ixz="3.18003675694284E-07" iyy="6.91333280651081E-06" iyz="7.37726682706417E-19" izz="2.24270431912283E-06" />
    </inertial>
    <visual>
      <origin xyz="0 0 0" rpy="0 0 0" />
      <geometry>
        <mesh filename="meshes/gripper/visual/outer_finger.stl" />
      </geometry>
      <material name="gripper_black" />
    </visual>
    <collision>
      <origin xyz="0 0 0" rpy="0 0 0" />
      <geometry>
        <mesh filename="meshes/gripper/collision/outer_finger.stl" />
      </geometry>
    </collision>
  </link>

  <joint name="right_outer_finger_joint" type="fixed">
    <origin xyz="0.0317095909367246 0 -0.0016013564954687" rpy="0 0 0" />
    <parent link="right_outer_knuckle" />
    <child link="right_outer_finger" />
    <axis xyz="0 1 0" />
  </joint>

</robot>